<!DOCTYPE html>
<html lang="en">
<head>
	<meta charset="UTF-8">
	<meta name="viewport" content="width=device-width, initial-scale=1.0">
	<meta http-equiv="X-UA-Compatible" content="ie=edge">
	<title>Chapitre 5 - Gestion d’erreurs et mécanisme d’exceptions</title>
	<script src="/deck.js" defer></script>
	<style>
		pre > code {
			font-size: 75% !important;
		}
	</style>
</head>
<body>
	<section>
		<h1>IN2T - Informatique <small>Gestion d’erreurs et mécanisme d’exceptions</small></h1>
		<p>Quentin Lurkin</p>
	</section>
	<section>
		<h2>Rappels</h2>
		
		<ul>
			<li>
				Création d'<strong>interface graphique</strong> 
				
				<ul>
					<li>
						Création de la fenêtre principale et de widgets
					</li>
					<li>
						Gestionnaire de mise en page et placement des widgets
					</li>
				</ul>
			</li>
			<li>
				Programmation <strong>évènementielle</strong> 
				
				<ul>
					<li>
						Application graphique
					</li>
					<li>
						Gestionnaire d'évènements et binding de fonctions
					</li>
				</ul>
			</li>
		</ul>
		
		
	</section>
	<section>
		<h2>Objectifs</h2>
		
		
		<ul>
			<li>
				Gestion d'<strong>erreurs</strong> 
				
				<ul>
					<li>
						Programmation défensive
					</li>
					<li>
						Spécification
					</li>
					<li>
						Instruction <code class="lang-python">assert</code>
					</li>
				</ul>
			</li>
			<li>
				Mécanisme d'<strong>exception</strong> 
				
				<ul>
					<li>
						Instruction <code class="lang-python">try-except-finally</code>
					</li>
					<li>
						instruction <code class="lang-python">raise</code>
					</li>
					<li>
						Définition d'une nouvelle exception
					</li>
				</ul>
			</li>
		</ul>
		
		
	</section>
	<section class="full">
		<h2>Gestion d’erreurs</h2>
		<img src="images/1401175133_e76fbb87d5_o.jpg" alt="">
	</section>
	<section>
		<h2>Trace d'erreur (1)</h2>
		
		
		<ul>
			<li>
				Une erreur d'exécution imprime une <strong>trace d'erreur</strong> 
				
				<small>Chemin d'exécution complet qui a provoqué l'erreur</small>
			</li>
		</ul>
		
		
		
		<pre><code class="lang-python">
			def percentage(score, total):
				return score / total * 100
			
			print('Alexis a obtenu', percentage(18, 20), '%')
			print('Sébastien a obtenu', percentage(6, 0), '%')
		</code></pre>
		<pre><code class="lang-plaintext">
			Alexis a obtenu 90.0 %
			Traceback (most recent call last):
				File "program.py", line 5, in &lt;module>
					print('Sébastien a obtenu', percentage(6, 0), '%')
				File "program.py", line 2, in percentage
					return score / total * 100
			ZeroDivisionError: division by zero
		</code></pre>
			
	</section>
	<section>
		<h2>Trace d'erreur (2)</h2>
		
		
		<ul>
			<li>
				L'erreur a comme <strong>origine</strong> l'exécution de l'instruction en ligne 5
				<pre><code class="lang-plaintext">
					File "program.py", line 5, in &lt;module>
						print('Sébastien a obtenu', percentage(6, 0), '%')
				</code></pre>
			</li>
			<li>
				L'erreur est dans la <strong>fonction <code>percentage()</code></strong>
				<pre><code class="lang-plaintext">
					File "program.py", line 2, in percentage
						return score / total * 100
				</code></pre>
			</li>
			<li>
				L'erreur est de type <strong>division par zéro</strong>
				<pre><code class="lang-plaintext">
					ZeroDivisionError: division by zero
				</code></pre>
			</li>
		</ul>
			
			
	</section>
	<section>
		<h2>Gestion d'erreurs</h2>
		
		
		<ul>
			<li>
				Prendre en compte <strong>tous les cas</strong> possibles d'exécution 
				
				<small>Prévoir une valeur de retour spéciale en cas d'erreur</small>
			</li>
		</ul>
		
		
		
		<pre><code class="lang-python">
			def percentage(score, total):
				if total != 0:
					return score / total * 100
				return None
		</code></pre>
		<pre><code class="lang-plaintext">
			Alexis a obtenu 90.0 %
			Sébastien a obtenu None %
		</code></pre>
		
	</section>
	<section>
		<h2>Types d'erreur</h2>
		
		
		<ul>
			<li>
				On peut considérer <strong>trois types d'erreur</strong> possibles 
				
				<ul>
					<li>
						<b>Erreur de syntaxe</b>
						
						<small>Code source mal formé</small>
					</li>
					<li>
						<b>Erreur d'exécution</b> 
						
						<small>Exécution d'une opération interdite</small>
					</li>
					<li>
						<b>Erreur logique</b> 
						
						<small>Programme ne calcule pas ce qu'il faut</small>
					</li>
				</ul>
			</li>
			<li>
				Le troisième type est le plus <strong>difficile à déceler</strong> 
				
				<small>Il faut pouvoir vérifier que le programme fait ce qu'il faut</small>
			</li>
		</ul>
		
		
	</section>
	<section>
		<h2>Erreur de syntaxe</h2>
		
		
		<ul>
			<li>
				Erreur détectée <strong>lors de l'exécution</strong> de l'instruction 
				
				<small>Python est en effet un langage interprété</small>
			</li>
			<li>
				Code source du programme contient des <strong>fautes de syntaxe</strong> 
				
				<small>Un peu comme l'orthographe en français</small>
			</li>
		</ul>
		
		
		
		<pre><code class="lang-python">
			score = 12
			if score > 10
				print('Vous avez réussi !')
		</code></pre>
		<pre><code class="lang-plaintext">
			File "program.py", line 2
				if score > 10
							^
			SyntaxError: invalid syntax
		</code></pre>
		
	</section>
	<section>
		<h2>Erreur d'exécution</h2>
		
		
		<ul>
			<li>
				Erreur produite <strong>durant l'exécution</strong> d'une opération interdite 
				
				<small>Division par zéro, indice en dehors d'une liste...</small>
			</li>
		</ul>
		
		
		
		<pre><code class="lang-python">
			data = [1, 2, 3]
			
			i = 0
			while i &lt;= len(data):
				print(data[i])
				i += 1
		</code></pre>
		<pre><code class="lang-plaintext">
			1
			2
			3
			Traceback (most recent call last):
				File "program.py", line 5, in &lt;module>
					print(data[i])
			IndexError: list index out of range
		</code></pre>
		
	</section>
	<section>
		<h2>Erreur logique</h2>
		
		
		<ul>
			<li>
				Le programme ne <strong>calcule pas ce qu'il faut</strong> 
				
				<small>Aucune erreur de syntaxe ou d'exécution ne se produit</small>
			</li>
		</ul>
		
		
		
		<pre><code class="lang-python">
			def perimeter(length, width):
				return length + width * 2
			
			print(perimeter(2, 1))
		</code></pre>
		<pre><code class="lang-plaintext">
			4
		</code></pre>
		
		<ul>
			<li>
				Il peut être utile de décrire clairement ce que la fonction devrait faire 
				
				<small>Pour s'assurer qu'il y a bien une erreur</small>
			</li>
		</ul>
		
		
	</section>
	<section>
		<h2>Documentation</h2>
		
		<ul>
			<li>
				La <strong>documentation</strong> d'une fonction décrit le résultat produit 
				
				<small>Permet à un utilisateur d'interpréter le résultat de l'appel</small>
			</li>
			<li>
				Description de <strong>conditions</strong> sur les paramètres 
				
				<small>Et de la valeur de retour si elles ne sont pas satisfaites</small>
			</li>
		</ul>
		
		
		
		<pre><code class="lang-python">
			# Renvoie le pourcentage d'une note étant donné :
			# - "score" contient la note obtenue (flottant)
			# - "total" est la note maximale atteignable (flottant)
			#
			# Si total &lt;= 0, score &lt; 0 ou score > total, alors renvoie None
			def percentage(score, total):
				if total > 0 and (0 &lt;= score &lt;= total):
					return score / total * 100
				return None
		</code></pre>
		
	</section>
	<section>
		<h2>Instruction <code class="lang-python">assert</code> (1)</h2>
		
		<ul>
			<li>
				Vérification de <strong>conditions sensées être vraies</strong> avec <code class="lang-python">assert</code> 
				
				<small>On vérifie notamment les conditionssur les paramètres avec cette instruction</small>
			</li>
			<li>
				Un programme <strong>doit fonctionner</strong> si on supprime les assertions 
				
				<small>Elles ne doivent pas faire partie du code fonctionnel</small>
			</li>
		</ul>
		
		<pre><code class="lang-python">
			def percentage(score, total):
				assert total > 0, 'total doit être strictement positif'
				assert 0 <= score, 'score doit être positif'
				assert score <= total, 'score doit être inférieur à total'
				return score / total * 100
		</code></pre>
		
	</section>
	<section>
		<h2>Instruction <code class="lang-python">assert</code> (2)</h2>
		
		
		<ul>
			<li>
				<strong>Arrêt du programme</strong> en cas d'erreur d'assertion 
				
				<small>Avec affichage d'un message d'information</small>
			</li>
			<li>
				Empêche des erreurs qui <strong>ne devraient pas</strong> se produire 
				
				<small>Le programme peut être modifié pour les éviter</small>
			</li>
		</ul>
		
		
		
		<pre><code class="lang-python">
			print(percentage(15, 20), '%')
			print(percentage(22, 20), '%')
		</code></pre>
		<pre><code class="lang-plaintext">
			75.0 %
			Traceback (most recent call last):
				File "program.py", line 8, in &lt;module>
					print(percentage(22, 20), '%')
				File "program.py", line 4, in percentage
					assert score <= total, 'score doit être inférieur à total'
			AssertionError: score doit être inférieur à total
		</code></pre>
	</section>
	<section class="full deck-only">
		<img src="images/4241208915_832187dfcb_b.jpg" alt="">
		<div style="position: absolute; bottom: 2em; right: 2em; background-color: rgba(255, 255, 255, 0.7); width: 60%; padding: 1em; font-style: italic;">
			“Always code as if the guy who ends up maintaining your code will be a violent psychopath who knows where you live.”<br>— Martin Golding
		</div>
	</section>
	<section>
		<h2>Programmation défensive</h2>
		
		<ul>
			<li>
				<b>Programmation défensive</b>
				
				<ul>
					<li>
						Utilisation de l'instruction <code class="lang-python">assert</code>
					</li>
					<li>
						On suppose les préconditions remplies
					</li>
					<li>
						Peut être pratiquée au sein d'un module
						<small>Se pratique sur du code dont vous avez le contrôle</small>
					</li>
				</ul>
			</li>
			<li>
				<b>Gestion d'erreur</b>
				
				<ul>
					<li>
						Utilisation de l'instruction <code class="lang-python">if-else</code>
					</li>
					<li>
						On vérifie les conditions nécessaires sur les données
					</li>
					<li>
						Doit être pratiquée pour interface avec l'extérieur
						<small>Vérification de toutes données hors contrôle</small>
					</li>
				</ul>
			</li>
		</ul>
		
		
	</section>
		
	<section>
		<h2>Nombres premiers (1)</h2>
		
		<ul>
			<li>
				Afficher les <code class="lang-python">n</code> premier <strong>nombres premiers</strong>
			</li>
			<li>
				Fonction auxiliaire en programmation défensive 
				
				<small>Vérification des préconditions avec l'instruction <code class="lang-python">assert</code></small>
			</li>
		</ul>
		
		<pre><code class="lang-python">
			def _isPrime(x):
				assert type(x) == int, "must be an int"
				assert x > 1, "must be greater than 1"
				
				for d in range(2, x):
					if x % d == 0:
						return False
				return True
		</code></pre>
		
	</section>
	<section>
		<h2>Nombres premiers (2)</h2>
		
		<ul>
			<li>
				La fonction principale <strong>vérifie les paramètres</strong> 
				
				<small>Renvoi de <code class="lang-python">False</code> en cas de souci</small>
			</li>
		</ul>
		
		<pre><code class="lang-python">
			def printPrimes(n):
				if type(n) != int or n < 0:
					return False
				
				count = 0
				i = 2
				while count < n:
					if _isPrime(i):
						print(i)
						count += 1
					i+=1
				return True
		</code></pre>
	</section>
	<section class="full">
		<h2>Mécanisme d’exception</h2>
		<img src="images/510673513_a0dd2626a3_o.jpg" alt="">
	</section>
	<section>
		<h2>Instruction <code class="lang-python">try-except</code> (1)</h2>
		
		<ul>
			<li>
				<strong>Code risqué</strong> placé dans un bloc <code class="lang-python">try</code> 
				
				<small>N'y placer que le code risqué et tout code qui en dépend</small>
			</li>
			<li>
				<strong>Erreurs capturées</strong> dans le bloc <code class="lang-python">except</code> 
				
				<small>Y placer le code à exécuter en cas de capture d'une erreur</small>
			</li>
		</ul>
		
		
		
		<pre><code class="lang-python">
			from datetime import *
			
			birthyear = input('Année de naissance ? ')
			
			try:
				now = datetime.now()
				age = now.year - int(birthyear)
				print('Tu as', age, 'ans')
			except:
				print('Erreur')
		</code></pre>
	</section>
	<section>
		<h2>Instruction <code class="lang-python">try-except</code> (2)</h2>
		
		
		<ul>
			<li>
				Si l'utilisateur entre un nombre entier, <strong>pas d'erreurs</strong>
				
				<pre><code class="lang-plaintext">
					Année de naissance ? 1982
					Tu as 36 ans
				</code></pre>
			</li>
			<li>
				Si l'utilisateur n'entre pas un nombre entier, <strong>erreur capturée</strong>
				
				<pre><code class="lang-plaintext">
					Année de naissance ? BLA
					Erreur
				</code></pre>
			</li>
		</ul>
		
		
	</section>
	<section>
		<h2>Validité d'une donnée</h2>
		
		
		<ul>
			<li>
				Demande d'une valeur à l'utilisateur <strong>en boucle</strong> 
				
				<small>Tant que la valeur demandée n'est pas du bon type</small>
			</li>
		</ul>
		
		
		
		<pre><code class="lang-python">
			from datetime import *
			
			valid = False
			while not valid:
				birthyear = input('Année de naissance ? ')
				try:
					birthyear = int(birthyear)
					valid = True
				except:
					print('Veuillez entrer un nombre entier')
			
			now = datetime.now()
			age = now.year - birthyear
			print('Tu as', age, 'ans')
		</code></pre>
		
	</section>
	<section>
		<h2>Vérifier le type d'erreur (1)</h2>
		
		<ul>
			<li>
				Plusieurs <strong>types d'erreur</strong> sont possibles 
				
				<small>Division par zéro, erreur de conversion...</small>
			</li>
			<li>
				Toutes les erreurs sont capturées par l'<strong>instruction <code class="lang-python">except</code></strong> 
				
				<small>Possibilité de capturer les erreurs de manière spécifique</small>
			</li>
		</ul>
		
		<pre><code class="lang-python">
			try:
				a = int(input('a ? '))
				b = int(input('b ? '))
				print(a, '/', b, '=', a / b)
			except:
				print('Erreur')
		</code></pre>
	</section>
	<section>
		<h2>Vérifier le type d'erreur (2)</h2>
		
		
		<ul>
			<li>
				Une <strong>exception</strong> est un objet qui représente une erreur 
				
				<small>L'objet est généralement de type <code class="lang-python">Exception</code></small>
			</li>
			<li>
				Types spécifiques pour différencier les <strong>types d'erreurs</strong> 
				
				<small>ZeroDivisionError, ValueError...</small>
			</li>
		</ul>
		
		
		
		<pre><code class="lang-python">
			import sys
			
			try:
				a = int(input('a ? '))
				b = int(input('b ? '))
				print(a, '/', b, '=', a / b)
			except Exception as e:
				print(type(e))
				print(e)
		</code></pre>
		
	</section>
	<section>
		<h2>Vérifier le type d'erreur (3)</h2>
		
		
		<ul>
			<li>
				Division par zéro
				
				<pre><code class="lang-plaintext">
					a ? deux
					&lt;class 'ValueError'>
					invalid literal for int() with base 10: 'deux'
				</code></pre>
			</li>
			<li>
				Erreur de conversion
				
				<pre><code class="lang-plaintext">
					a ? 2 
					b ? 0
					&lt;class 'ZeroDivisionError'>
					division by zero
				</code></pre>
			</li>
		</ul>
	</section>
	<section>
		<h2>Capturer une erreur spécifique (1)</h2>
		
		<ul>
			<li>
				<strong>Gestionnaire d'erreurs</strong> différent pour chaque type d'erreur 
				
				<small>Il suffit de déclarer un bloc <code class="lang-python">except</code> par erreur à capturer</small>
			</li>
			<li>
				Attention à l'<strong>ordre de capture</strong> (de haut en bas) 
				
				<small>Il faut classer les erreurs de la plus à la moins spécificité</small>
			</li>
		</ul>
		
		<pre><code class="lang-python">
			import sys
			
			try:
				a = int(input('a ? '))
				b = int(input('b ? '))
				print(a, '/', b, '=', a / b)
			except ValueError:
				print('Erreur de conversion')
			except ZeroDivisionError:
				print('Division par zéro')
			except:
				print('Autre erreur')
		</code></pre>
		
	</section>
	<section>
		<h2>Capturer une erreur spécifique (2)</h2>
		
		<pre><code class="lang-python">
			import sys
			
			try:
				a = int(input('a ? '))
				b = int(input('b ? '))
				print(a, '/', b, '=', a / b)
			except Exception:
				print('Erreur')
			except ValueError:
				print('Erreur de conversion')
			except ZeroDivisionError:
				print('Division par zéro')
		</code></pre>
		<pre><code class="lang-plaintext">
			a ? 2
			b ? 0
			Autre erreur
		</code></pre>
	</section>
	<section>
		<h2>Information sur une erreur</h2>
		
		
		<ul>
			<li>
				L'<strong>objet de l'exception</strong> peut contenir de l'information 
				
				<small>On peut accéder à des propriétés ou à des méthodes</small>
			</li>
		</ul>
		
		
		
		<pre><code class="lang-python">
			try:
				import mymod
			except SyntaxError as e:
				print(e)
				print('File:', e.filename)
				print('Line:', e.lineno)
				print('Text:', e.text)
		</code></pre>
		<pre><code class="lang-plaintext">
			can't assign to literal (mymod.py, line 1)
			File: /Users/combefis/Desktop/mymod.py
			Line: 1
			Text: 2 = x
		</code></pre>
	</section>
	<section>
		<h2>Gestionnaire d'erreurs partagé</h2>
		
		
		<ul>
			<li>
				<strong>Même gestionnaire d'erreurs</strong> pour différents types 
				
				<small>Tuple d'exception fourni à l'instruction <code class="lang-python">except</code></small>
			</li>
		</ul>
		
		
		
		<pre><code class="lang-python">
			try:
				a = int(input('a ? '))
				b = int(input('b ? '))
				print(a / b)
			except (ZeroDivisionError, ValueError):
				print('Erreur de calcul')
			except:
				print('Erreur')
		</code></pre>
		<pre><code class="lang-plaintext">
			a ? 1
			b ? 0
			Erreur de calcul
		</code></pre>
	</section>
	<section>
		<h2>Propagation d'erreur (1)</h2>
		
		
		<ul>
			<li>
				Une <strong>erreur non capturée</strong> remonte les appels de fonction 
				
				<small>Jusqu'à être attrapée ou remonté jusqu'au bout</small>
			</li>
			<li>
				La <strong>trace d'erreur</strong> montre le trajet pris par l'exception 
				
				<small>En la lisant à l'envers, on peut suivre la propagation</small>
			</li>
		</ul>
	</section>
	<section>
		<h2>Propagation d'erreur (2)</h2>
		
		
		<ul>
			<li>
				<strong>Passage</strong> de <code class="lang-python">fun</code> à <code class="lang-python">compute</code> au programme principal
			</li>
		</ul>
		
		
		
		<pre><code class="lang-python">
			def fun():
				print(1 / 0)
			
			def compute():
				fun()
			
			compute()
		</code></pre>
		<pre><code class="lang-plaintext">
			Traceback (most recent call last):
				File "program.py", line 7, in &lt;module>
					compute()
				File "program.py", line 5, in compute
					fun()
				File "program.py", line 2, in fun
					print(1 / 0)
			ZeroDivisionError: division by zero
		</code></pre>
			
		</section>
		<section>
			<h2>Propagation d'erreur (3)</h2>
			
			
			<ul>
				<li>
					Exception <strong>interceptée</strong> dans la fonction <code class="lang-python">compute</code>
				</li>
			</ul>
			
			
			
			<pre><code class="lang-python">
				def fun():
					print(1 / 0)
				
				def compute():
					try:
						fun()
					except:
						print('Erreur.')
				
				compute()
			</code></pre>
			<pre><code class="lang-plaintext">
				Erreur.
			</code></pre>
			
		</section>
		<section>
			<h2>Bloc <code class="lang-python">finally</code> (1)</h2>
			
			
			<ul>
				<li>
					Le bloc <code class="lang-python">finally</code> s'exécute <strong>dans tous les cas</strong> 
					
					<small>Après le bloc <code class="lang-python">try</code> ou l'<code class="lang-python">except</code> en cas d'erreur</small>
				</li>
				<li>
					Notamment utilisé pour faire du <strong>nettoyage</strong> 
					
					<small>Par exemple pour libérer des ressources qui ont été allouées</small>
				</li>
			</ul>
		</section>
	<section>
		<h2>Bloc <code class="lang-python">finally</code> (2)</h2>
		
		
		<ul>
			<li>
				Bloc <code class="lang-python">finally</code> <strong>exécuté à tous les coups</strong> avant la fin du calcul
			</li>
		</ul>
		
		
		
		<pre><code class="lang-python">
			print('Début du calcul.')
			try:
				a = int(input('a ? '))
				b = int(input('b ? '))
				print('Résultat :', a / b)
			except:
				print('Erreur.')
			finally:
				print('Nettoyage de la mémoire.')
				print('Fin du calcul.')
		</code></pre>
		<pre><code class="lang-plaintext">
			Début du calcul.
			a ? 2
			b ? 8
			Résultat : 0.25
			Nettoyage de la mémoire.
			Fin du calcul.
		</code></pre>
		
	</section>
	<section>
		<h2>Générer une erreur</h2>
		
		<ul>
			<li>
				L'<strong>instruction <code class="lang-python">raise</code></strong> permet de générer une erreur 
				
				<small>Création d'un objet du type de l'exception</small>
			</li>
		</ul>
		
		
		<pre><code class="lang-python">
			def fact(n):
				if n < 0:
					raise ArithmeticError()
				if n == 0:
					return 1
				return n * fact(n - 1)
			
			try:
				n = int(input('Entrez un nombre : '))
				print(fact(n))
			except ArithmeticError:
				print('Veuillez entrer un nombre positif.')
			except:
				print('Veuillez entrer un nombre.')
		</code></pre>

		<pre><code class="lang-plaintext">
			Entrez un nombre : -12
			Veuillez entrer un nombre positif.
		</code></pre>
		
	</section>
	<section>
		<h2>Définir une erreur (1)</h2>
		
		<ul>
			<li>
				<strong>Définition d'une erreur</strong> en définissant une nouvelle classe 
				
				<small>La classe est créée à partir de la classe <code class="lang-python">Exception</code></small>
			</li>
			<li>
				L'<strong>instruction <code class="lang-python">pass</code></strong> ne fait rien
			</li>
		</ul>
		
		
		<pre><code class="lang-python">
			from math import sqrt
			
			class NoRootException(Exception):
				pass
			
			def trinomialroots(a, b, c):
				delta = b ** 2 - 4 * a * c
				if delta < 0:
					raise NoRootException()
				if delta == 0:
					return (-b / (2 * a),)
				x1 = (-b + sqrt(delta)) / (2 * a)
				x2 = (-b - sqrt(delta)) / (2 * a)
				return (x1, x2)
		</code></pre>
		
	</section>
	<section>
		<h2>Définir une erreur (2)</h2>
		
		<ul>
			<li>
				<strong>Capture de la nouvelle erreur</strong> avec l'instruction <code class="lang-python">except</code> 
				
				<small>Le nouveau type d'erreur est maintenant connu par Python</small>
			</li>
		</ul>
		
		<pre><code class="lang-python">
			try:
				print(trinomialroots(1, 0, 2))
			except NoRootException:
				print('Pas de racine réelle.')
			except:
				print('Erreur')
		</code></pre>
		<pre><code class="lang-plaintext">
			Pas de racine réelle.
		</code></pre>
		
	</section>
	<section>
		<h2>Exception paramétrée</h2>
		
		<ul>
			<li>
				Stockage d'un <strong>paramètre</strong> dans l'exception
			</li>
		</ul>
		
		
		<pre><code class="lang-python">
			class NoRootException(Exception):
				def __init__(self, delta):
					self.__delta = delta
			
				@property
				def delta(self):
					return self.__delta
			
			def trinomialroots(a, b, c):
				delta = b ** 2 - 4 * a * c
				if delta < 0:
					raise NoRootException(delta)
				if delta == 0:
					return (-b / (2 * a),)
				x1 = (-b + sqrt(delta)) / (2 * a)
				x2 = (-b - sqrt(delta)) / (2 * a)
				return (x1, x2)
			
			try:
				print(trinomialroots(1, 0, 2))
			except NoRootException as e:
				print('Pas de racine réelle (delta = {})'.format(e.delta))
			except:
				print('Erreur')
			
		</code></pre>
		<pre><code class="lang-plaintext">
			Pas de racine réelle (delta = -8)
		</code></pre>
		
	</section>
	<section>
		<h2>Quand utiliser les erreurs ?</h2>
		
		
		<ul>
			<li>
				<strong>Toujours</strong> vérifier les données provenant de l'<strong>extérieur</strong> 
				
				<small>Lecture avec <code class="lang-python">input</code>, lecture d'un fichier...</small>
			</li>
			<li>
				Lors d'un <strong>appel à une fonction</strong> d'un module 
				
				<small>Lire la documentation de la fonction, pour les erreurs potentielles</small>
			</li>
			<li>
				Quand on définit une <strong>librairie</strong> 
				
				<small>Pour les fonctions publiques offertes à l'extérieur</small>
			</li>
		</ul>
		
		
	</section>
	<section>
		<h2>Crédits</h2>
		
		<ul>
			<li>
				https://www.flickr.com/photos/mstibbetts/1401175133
			</li>
			<li>
				http://www.flickr.com/photos/tetezinharomana/7152072635/
			</li>
			<li>
				https://www.flickr.com/photos/mbiskoping/510673513
			</li>
		</ul>
	</section>
					
</body>
</html>
						
